INFO:werkzeug: * Running on http://0.0.0.0:3111/ (Press CTRL+C to quit)
INFO:app:Status request successfull
ERROR:app:Exception on /healthz [GET]
Traceback (most recent call last):
  File "/Users/alex/opt/anaconda3/lib/python3.8/site-packages/flask/app.py", line 2447, in wsgi_app
    response = self.full_dispatch_request()
  File "/Users/alex/opt/anaconda3/lib/python3.8/site-packages/flask/app.py", line 1952, in full_dispatch_request
    rv = self.handle_user_exception(e)
  File "/Users/alex/opt/anaconda3/lib/python3.8/site-packages/flask/app.py", line 1821, in handle_user_exception
    reraise(exc_type, exc_value, tb)
  File "/Users/alex/opt/anaconda3/lib/python3.8/site-packages/flask/_compat.py", line 39, in reraise
    raise value
  File "/Users/alex/opt/anaconda3/lib/python3.8/site-packages/flask/app.py", line 1950, in full_dispatch_request
    rv = self.dispatch_request()
  File "/Users/alex/opt/anaconda3/lib/python3.8/site-packages/flask/app.py", line 1936, in dispatch_request
    return self.view_functions[rule.endpoint](**req.view_args)
  File "app.py", line 84, in healthcheck
    return jsonify(response)
  File "/Users/alex/opt/anaconda3/lib/python3.8/site-packages/flask/json/__init__.py", line 370, in jsonify
    dumps(data, indent=indent, separators=separators) + "\n",
  File "/Users/alex/opt/anaconda3/lib/python3.8/site-packages/flask/json/__init__.py", line 211, in dumps
    rv = _json.dumps(obj, **kwargs)
  File "/Users/alex/opt/anaconda3/lib/python3.8/json/__init__.py", line 234, in dumps
    return cls(
  File "/Users/alex/opt/anaconda3/lib/python3.8/json/encoder.py", line 199, in encode
    chunks = self.iterencode(o, _one_shot=True)
  File "/Users/alex/opt/anaconda3/lib/python3.8/json/encoder.py", line 257, in iterencode
    return _iterencode(o, 0)
  File "/Users/alex/opt/anaconda3/lib/python3.8/site-packages/flask/json/__init__.py", line 100, in default
    return _json.JSONEncoder.default(self, o)
  File "/Users/alex/opt/anaconda3/lib/python3.8/json/encoder.py", line 179, in default
    raise TypeError(f'Object of type {o.__class__.__name__} '
TypeError: Object of type Response is not JSON serializable
INFO:werkzeug:127.0.0.1 - - [08/Jun/2021 19:25:03] "[35m[1mGET /healthz HTTP/1.1[0m" 500 -
ERROR:app:Exception on /metrics [GET]
Traceback (most recent call last):
  File "/Users/alex/opt/anaconda3/lib/python3.8/site-packages/flask/app.py", line 2447, in wsgi_app
    response = self.full_dispatch_request()
  File "/Users/alex/opt/anaconda3/lib/python3.8/site-packages/flask/app.py", line 1952, in full_dispatch_request
    rv = self.handle_user_exception(e)
  File "/Users/alex/opt/anaconda3/lib/python3.8/site-packages/flask/app.py", line 1821, in handle_user_exception
    reraise(exc_type, exc_value, tb)
  File "/Users/alex/opt/anaconda3/lib/python3.8/site-packages/flask/_compat.py", line 39, in reraise
    raise value
  File "/Users/alex/opt/anaconda3/lib/python3.8/site-packages/flask/app.py", line 1950, in full_dispatch_request
    rv = self.dispatch_request()
  File "/Users/alex/opt/anaconda3/lib/python3.8/site-packages/flask/app.py", line 1936, in dispatch_request
    return self.view_functions[rule.endpoint](**req.view_args)
  File "app.py", line 93, in metrics
    response=json.dumps({"count_connections":db_connection_count, "post_count":count_posts}),
  File "/Users/alex/opt/anaconda3/lib/python3.8/site-packages/flask/json/__init__.py", line 211, in dumps
    rv = _json.dumps(obj, **kwargs)
  File "/Users/alex/opt/anaconda3/lib/python3.8/json/__init__.py", line 234, in dumps
    return cls(
  File "/Users/alex/opt/anaconda3/lib/python3.8/json/encoder.py", line 199, in encode
    chunks = self.iterencode(o, _one_shot=True)
  File "/Users/alex/opt/anaconda3/lib/python3.8/json/encoder.py", line 257, in iterencode
    return _iterencode(o, 0)
  File "/Users/alex/opt/anaconda3/lib/python3.8/site-packages/flask/json/__init__.py", line 100, in default
    return _json.JSONEncoder.default(self, o)
  File "/Users/alex/opt/anaconda3/lib/python3.8/json/encoder.py", line 179, in default
    raise TypeError(f'Object of type {o.__class__.__name__} '
TypeError: Object of type Row is not JSON serializable
INFO:werkzeug:127.0.0.1 - - [08/Jun/2021 19:25:08] "[35m[1mGET /metrics HTTP/1.1[0m" 500 -
INFO:werkzeug: * Running on http://0.0.0.0:3111/ (Press CTRL+C to quit)
INFO:werkzeug:127.0.0.1 - - [08/Jun/2021 19:30:01] "[37mGET / HTTP/1.1[0m" 200 -
ERROR:app:Exception on /metrics [GET]
Traceback (most recent call last):
  File "/Users/alex/opt/anaconda3/lib/python3.8/site-packages/flask/app.py", line 2447, in wsgi_app
    response = self.full_dispatch_request()
  File "/Users/alex/opt/anaconda3/lib/python3.8/site-packages/flask/app.py", line 1952, in full_dispatch_request
    rv = self.handle_user_exception(e)
  File "/Users/alex/opt/anaconda3/lib/python3.8/site-packages/flask/app.py", line 1821, in handle_user_exception
    reraise(exc_type, exc_value, tb)
  File "/Users/alex/opt/anaconda3/lib/python3.8/site-packages/flask/_compat.py", line 39, in reraise
    raise value
  File "/Users/alex/opt/anaconda3/lib/python3.8/site-packages/flask/app.py", line 1950, in full_dispatch_request
    rv = self.dispatch_request()
  File "/Users/alex/opt/anaconda3/lib/python3.8/site-packages/flask/app.py", line 1936, in dispatch_request
    return self.view_functions[rule.endpoint](**req.view_args)
  File "app.py", line 93, in metrics
    response=json.dumps({"count_connections":db_connection_count, "post_count":count_posts}),
  File "/Users/alex/opt/anaconda3/lib/python3.8/site-packages/flask/json/__init__.py", line 211, in dumps
    rv = _json.dumps(obj, **kwargs)
  File "/Users/alex/opt/anaconda3/lib/python3.8/json/__init__.py", line 234, in dumps
    return cls(
  File "/Users/alex/opt/anaconda3/lib/python3.8/json/encoder.py", line 199, in encode
    chunks = self.iterencode(o, _one_shot=True)
  File "/Users/alex/opt/anaconda3/lib/python3.8/json/encoder.py", line 257, in iterencode
    return _iterencode(o, 0)
  File "/Users/alex/opt/anaconda3/lib/python3.8/site-packages/flask/json/__init__.py", line 100, in default
    return _json.JSONEncoder.default(self, o)
  File "/Users/alex/opt/anaconda3/lib/python3.8/json/encoder.py", line 179, in default
    raise TypeError(f'Object of type {o.__class__.__name__} '
TypeError: Object of type Row is not JSON serializable
INFO:werkzeug:127.0.0.1 - - [08/Jun/2021 19:30:07] "[35m[1mGET /metrics HTTP/1.1[0m" 500 -
INFO:app:Status request successfull
INFO:werkzeug:127.0.0.1 - - [08/Jun/2021 19:30:26] "[37mGET /healthz HTTP/1.1[0m" 200 -
INFO:werkzeug: * Running on http://0.0.0.0:3111/ (Press CTRL+C to quit)
ERROR:app:Exception on /metrics [GET]
Traceback (most recent call last):
  File "/Users/alex/opt/anaconda3/lib/python3.8/site-packages/flask/app.py", line 2447, in wsgi_app
    response = self.full_dispatch_request()
  File "/Users/alex/opt/anaconda3/lib/python3.8/site-packages/flask/app.py", line 1952, in full_dispatch_request
    rv = self.handle_user_exception(e)
  File "/Users/alex/opt/anaconda3/lib/python3.8/site-packages/flask/app.py", line 1821, in handle_user_exception
    reraise(exc_type, exc_value, tb)
  File "/Users/alex/opt/anaconda3/lib/python3.8/site-packages/flask/_compat.py", line 39, in reraise
    raise value
  File "/Users/alex/opt/anaconda3/lib/python3.8/site-packages/flask/app.py", line 1950, in full_dispatch_request
    rv = self.dispatch_request()
  File "/Users/alex/opt/anaconda3/lib/python3.8/site-packages/flask/app.py", line 1936, in dispatch_request
    return self.view_functions[rule.endpoint](**req.view_args)
  File "app.py", line 93, in metrics
    response=jsonify({"count_connections":db_connection_count, "post_count":count_posts}),
  File "/Users/alex/opt/anaconda3/lib/python3.8/site-packages/flask/json/__init__.py", line 370, in jsonify
    dumps(data, indent=indent, separators=separators) + "\n",
  File "/Users/alex/opt/anaconda3/lib/python3.8/site-packages/flask/json/__init__.py", line 211, in dumps
    rv = _json.dumps(obj, **kwargs)
  File "/Users/alex/opt/anaconda3/lib/python3.8/json/__init__.py", line 234, in dumps
    return cls(
  File "/Users/alex/opt/anaconda3/lib/python3.8/json/encoder.py", line 199, in encode
    chunks = self.iterencode(o, _one_shot=True)
  File "/Users/alex/opt/anaconda3/lib/python3.8/json/encoder.py", line 257, in iterencode
    return _iterencode(o, 0)
  File "/Users/alex/opt/anaconda3/lib/python3.8/site-packages/flask/json/__init__.py", line 100, in default
    return _json.JSONEncoder.default(self, o)
  File "/Users/alex/opt/anaconda3/lib/python3.8/json/encoder.py", line 179, in default
    raise TypeError(f'Object of type {o.__class__.__name__} '
TypeError: Object of type Row is not JSON serializable
INFO:werkzeug:127.0.0.1 - - [08/Jun/2021 19:31:23] "[35m[1mGET /metrics HTTP/1.1[0m" 500 -
INFO:app:Status request successfull
INFO:werkzeug:127.0.0.1 - - [08/Jun/2021 19:31:28] "[37mGET /healthz HTTP/1.1[0m" 200 -
ERROR:app:Exception on /metrics [GET]
Traceback (most recent call last):
  File "/Users/alex/opt/anaconda3/lib/python3.8/site-packages/flask/app.py", line 2447, in wsgi_app
    response = self.full_dispatch_request()
  File "/Users/alex/opt/anaconda3/lib/python3.8/site-packages/flask/app.py", line 1952, in full_dispatch_request
    rv = self.handle_user_exception(e)
  File "/Users/alex/opt/anaconda3/lib/python3.8/site-packages/flask/app.py", line 1821, in handle_user_exception
    reraise(exc_type, exc_value, tb)
  File "/Users/alex/opt/anaconda3/lib/python3.8/site-packages/flask/_compat.py", line 39, in reraise
    raise value
  File "/Users/alex/opt/anaconda3/lib/python3.8/site-packages/flask/app.py", line 1950, in full_dispatch_request
    rv = self.dispatch_request()
  File "/Users/alex/opt/anaconda3/lib/python3.8/site-packages/flask/app.py", line 1936, in dispatch_request
    return self.view_functions[rule.endpoint](**req.view_args)
  File "app.py", line 93, in metrics
    response=jsonify({"count_connections":db_connection_count, "post_count":count_posts}),
  File "/Users/alex/opt/anaconda3/lib/python3.8/site-packages/flask/json/__init__.py", line 370, in jsonify
    dumps(data, indent=indent, separators=separators) + "\n",
  File "/Users/alex/opt/anaconda3/lib/python3.8/site-packages/flask/json/__init__.py", line 211, in dumps
    rv = _json.dumps(obj, **kwargs)
  File "/Users/alex/opt/anaconda3/lib/python3.8/json/__init__.py", line 234, in dumps
    return cls(
  File "/Users/alex/opt/anaconda3/lib/python3.8/json/encoder.py", line 199, in encode
    chunks = self.iterencode(o, _one_shot=True)
  File "/Users/alex/opt/anaconda3/lib/python3.8/json/encoder.py", line 257, in iterencode
    return _iterencode(o, 0)
  File "/Users/alex/opt/anaconda3/lib/python3.8/site-packages/flask/json/__init__.py", line 100, in default
    return _json.JSONEncoder.default(self, o)
  File "/Users/alex/opt/anaconda3/lib/python3.8/json/encoder.py", line 179, in default
    raise TypeError(f'Object of type {o.__class__.__name__} '
TypeError: Object of type Row is not JSON serializable
INFO:werkzeug:127.0.0.1 - - [08/Jun/2021 19:31:33] "[35m[1mGET /metrics HTTP/1.1[0m" 500 -
INFO:werkzeug: * Running on http://0.0.0.0:3111/ (Press CTRL+C to quit)
ERROR:app:Exception on /metrics [GET]
Traceback (most recent call last):
  File "/Users/alex/opt/anaconda3/lib/python3.8/site-packages/flask/app.py", line 2447, in wsgi_app
    response = self.full_dispatch_request()
  File "/Users/alex/opt/anaconda3/lib/python3.8/site-packages/flask/app.py", line 1952, in full_dispatch_request
    rv = self.handle_user_exception(e)
  File "/Users/alex/opt/anaconda3/lib/python3.8/site-packages/flask/app.py", line 1821, in handle_user_exception
    reraise(exc_type, exc_value, tb)
  File "/Users/alex/opt/anaconda3/lib/python3.8/site-packages/flask/_compat.py", line 39, in reraise
    raise value
  File "/Users/alex/opt/anaconda3/lib/python3.8/site-packages/flask/app.py", line 1950, in full_dispatch_request
    rv = self.dispatch_request()
  File "/Users/alex/opt/anaconda3/lib/python3.8/site-packages/flask/app.py", line 1936, in dispatch_request
    return self.view_functions[rule.endpoint](**req.view_args)
  File "app.py", line 93, in metrics
    response=jsonify([
  File "app.py", line 94, in <listcomp>
    dict(count_connections=db_connection_count, post_count=row[0])
TypeError: 'int' object is not subscriptable
INFO:werkzeug:127.0.0.1 - - [08/Jun/2021 19:49:49] "[35m[1mGET /metrics HTTP/1.1[0m" 500 -
INFO:werkzeug: * Running on http://0.0.0.0:3111/ (Press CTRL+C to quit)
ERROR:app:Exception on /metrics [GET]
Traceback (most recent call last):
  File "/Users/alex/opt/anaconda3/lib/python3.8/site-packages/flask/app.py", line 2447, in wsgi_app
    response = self.full_dispatch_request()
  File "/Users/alex/opt/anaconda3/lib/python3.8/site-packages/flask/app.py", line 1952, in full_dispatch_request
    rv = self.handle_user_exception(e)
  File "/Users/alex/opt/anaconda3/lib/python3.8/site-packages/flask/app.py", line 1821, in handle_user_exception
    reraise(exc_type, exc_value, tb)
  File "/Users/alex/opt/anaconda3/lib/python3.8/site-packages/flask/_compat.py", line 39, in reraise
    raise value
  File "/Users/alex/opt/anaconda3/lib/python3.8/site-packages/flask/app.py", line 1950, in full_dispatch_request
    rv = self.dispatch_request()
  File "/Users/alex/opt/anaconda3/lib/python3.8/site-packages/flask/app.py", line 1936, in dispatch_request
    return self.view_functions[rule.endpoint](**req.view_args)
  File "app.py", line 93, in metrics
    response=[
  File "app.py", line 94, in <listcomp>
    dict(count_connections=db_connection_count, post_count=row[0])
TypeError: 'int' object is not subscriptable
INFO:werkzeug:127.0.0.1 - - [08/Jun/2021 19:50:52] "[35m[1mGET /metrics HTTP/1.1[0m" 500 -
INFO:werkzeug: * Running on http://0.0.0.0:3111/ (Press CTRL+C to quit)
ERROR:app:Exception on /metrics [GET]
Traceback (most recent call last):
  File "/Users/alex/opt/anaconda3/lib/python3.8/site-packages/flask/app.py", line 2447, in wsgi_app
    response = self.full_dispatch_request()
  File "/Users/alex/opt/anaconda3/lib/python3.8/site-packages/flask/app.py", line 1952, in full_dispatch_request
    rv = self.handle_user_exception(e)
  File "/Users/alex/opt/anaconda3/lib/python3.8/site-packages/flask/app.py", line 1821, in handle_user_exception
    reraise(exc_type, exc_value, tb)
  File "/Users/alex/opt/anaconda3/lib/python3.8/site-packages/flask/_compat.py", line 39, in reraise
    raise value
  File "/Users/alex/opt/anaconda3/lib/python3.8/site-packages/flask/app.py", line 1950, in full_dispatch_request
    rv = self.dispatch_request()
  File "/Users/alex/opt/anaconda3/lib/python3.8/site-packages/flask/app.py", line 1936, in dispatch_request
    return self.view_functions[rule.endpoint](**req.view_args)
  File "app.py", line 93, in metrics
    response=[
  File "app.py", line 95, in <listcomp>
    post_count=row[0])
TypeError: 'int' object is not subscriptable
INFO:werkzeug:127.0.0.1 - - [08/Jun/2021 19:51:41] "[35m[1mGET /metrics HTTP/1.1[0m" 500 -
INFO:werkzeug: * Running on http://0.0.0.0:3111/ (Press CTRL+C to quit)
ERROR:app:Exception on /metrics [GET]
Traceback (most recent call last):
  File "/Users/alex/opt/anaconda3/lib/python3.8/site-packages/flask/app.py", line 2447, in wsgi_app
    response = self.full_dispatch_request()
  File "/Users/alex/opt/anaconda3/lib/python3.8/site-packages/flask/app.py", line 1952, in full_dispatch_request
    rv = self.handle_user_exception(e)
  File "/Users/alex/opt/anaconda3/lib/python3.8/site-packages/flask/app.py", line 1821, in handle_user_exception
    reraise(exc_type, exc_value, tb)
  File "/Users/alex/opt/anaconda3/lib/python3.8/site-packages/flask/_compat.py", line 39, in reraise
    raise value
  File "/Users/alex/opt/anaconda3/lib/python3.8/site-packages/flask/app.py", line 1950, in full_dispatch_request
    rv = self.dispatch_request()
  File "/Users/alex/opt/anaconda3/lib/python3.8/site-packages/flask/app.py", line 1936, in dispatch_request
    return self.view_functions[rule.endpoint](**req.view_args)
  File "app.py", line 95, in metrics
    post_count=[row[0] for row in count_posts])
  File "app.py", line 95, in <listcomp>
    post_count=[row[0] for row in count_posts])
TypeError: 'int' object is not subscriptable
INFO:werkzeug:127.0.0.1 - - [08/Jun/2021 19:53:08] "[35m[1mGET /metrics HTTP/1.1[0m" 500 -
INFO:werkzeug: * Running on http://0.0.0.0:3111/ (Press CTRL+C to quit)
INFO:app:Metrics request successfull
ERROR:app:Exception on /metrics [GET]
Traceback (most recent call last):
  File "/Users/alex/opt/anaconda3/lib/python3.8/site-packages/flask/app.py", line 2447, in wsgi_app
    response = self.full_dispatch_request()
  File "/Users/alex/opt/anaconda3/lib/python3.8/site-packages/flask/app.py", line 1952, in full_dispatch_request
    rv = self.handle_user_exception(e)
  File "/Users/alex/opt/anaconda3/lib/python3.8/site-packages/flask/app.py", line 1821, in handle_user_exception
    reraise(exc_type, exc_value, tb)
  File "/Users/alex/opt/anaconda3/lib/python3.8/site-packages/flask/_compat.py", line 39, in reraise
    raise value
  File "/Users/alex/opt/anaconda3/lib/python3.8/site-packages/flask/app.py", line 1950, in full_dispatch_request
    rv = self.dispatch_request()
  File "/Users/alex/opt/anaconda3/lib/python3.8/site-packages/flask/app.py", line 1936, in dispatch_request
    return self.view_functions[rule.endpoint](**req.view_args)
  File "app.py", line 103, in metrics
    return jsonify(response)
  File "/Users/alex/opt/anaconda3/lib/python3.8/site-packages/flask/json/__init__.py", line 370, in jsonify
    dumps(data, indent=indent, separators=separators) + "\n",
  File "/Users/alex/opt/anaconda3/lib/python3.8/site-packages/flask/json/__init__.py", line 211, in dumps
    rv = _json.dumps(obj, **kwargs)
  File "/Users/alex/opt/anaconda3/lib/python3.8/json/__init__.py", line 234, in dumps
    return cls(
  File "/Users/alex/opt/anaconda3/lib/python3.8/json/encoder.py", line 199, in encode
    chunks = self.iterencode(o, _one_shot=True)
  File "/Users/alex/opt/anaconda3/lib/python3.8/json/encoder.py", line 257, in iterencode
    return _iterencode(o, 0)
  File "/Users/alex/opt/anaconda3/lib/python3.8/site-packages/flask/json/__init__.py", line 100, in default
    return _json.JSONEncoder.default(self, o)
  File "/Users/alex/opt/anaconda3/lib/python3.8/json/encoder.py", line 179, in default
    raise TypeError(f'Object of type {o.__class__.__name__} '
TypeError: Object of type Response is not JSON serializable
INFO:werkzeug:127.0.0.1 - - [08/Jun/2021 19:55:40] "[35m[1mGET /metrics HTTP/1.1[0m" 500 -
INFO:werkzeug: * Running on http://0.0.0.0:3111/ (Press CTRL+C to quit)
INFO:app:Metrics request successfull
INFO:werkzeug:127.0.0.1 - - [08/Jun/2021 19:57:04] "[35m[1mGET /metrics HTTP/1.1[0m" 500 -
ERROR:werkzeug:Error on request:
Traceback (most recent call last):
  File "/Users/alex/opt/anaconda3/lib/python3.8/site-packages/werkzeug/serving.py", line 323, in run_wsgi
    execute(self.server.app)
  File "/Users/alex/opt/anaconda3/lib/python3.8/site-packages/werkzeug/serving.py", line 314, in execute
    for data in application_iter:
  File "/Users/alex/opt/anaconda3/lib/python3.8/site-packages/werkzeug/wsgi.py", line 506, in __next__
    return self._next()
  File "/Users/alex/opt/anaconda3/lib/python3.8/site-packages/werkzeug/wrappers/base_response.py", line 45, in _iter_encoded
    for item in iterable:
TypeError: 'Response' object is not iterable
INFO:werkzeug: * Running on http://0.0.0.0:3111/ (Press CTRL+C to quit)
INFO:app:Metrics request successfull
INFO:werkzeug:127.0.0.1 - - [08/Jun/2021 19:58:40] "[35m[1mGET /metrics HTTP/1.1[0m" 500 -
ERROR:werkzeug:Error on request:
Traceback (most recent call last):
  File "/Users/alex/opt/anaconda3/lib/python3.8/site-packages/werkzeug/serving.py", line 323, in run_wsgi
    execute(self.server.app)
  File "/Users/alex/opt/anaconda3/lib/python3.8/site-packages/werkzeug/serving.py", line 312, in execute
    application_iter = app(environ, start_response)
  File "/Users/alex/opt/anaconda3/lib/python3.8/site-packages/flask/app.py", line 2464, in __call__
    return self.wsgi_app(environ, start_response)
  File "/Users/alex/opt/anaconda3/lib/python3.8/site-packages/flask/app.py", line 2454, in wsgi_app
    return response(environ, start_response)
  File "/Users/alex/opt/anaconda3/lib/python3.8/site-packages/werkzeug/wrappers/base_response.py", line 698, in __call__
    app_iter, status, headers = self.get_wsgi_response(environ)
  File "/Users/alex/opt/anaconda3/lib/python3.8/site-packages/werkzeug/wrappers/base_response.py", line 686, in get_wsgi_response
    headers = self.get_wsgi_headers(environ)
  File "/Users/alex/opt/anaconda3/lib/python3.8/site-packages/werkzeug/wrappers/base_response.py", line 634, in get_wsgi_headers
    content_length = sum(len(to_bytes(x, "ascii")) for x in self.response)
  File "/Users/alex/opt/anaconda3/lib/python3.8/site-packages/werkzeug/wrappers/base_response.py", line 634, in <genexpr>
    content_length = sum(len(to_bytes(x, "ascii")) for x in self.response)
  File "/Users/alex/opt/anaconda3/lib/python3.8/site-packages/werkzeug/_compat.py", line 202, in to_bytes
    raise TypeError("Expected bytes")
TypeError: Expected bytes
INFO:werkzeug: * Running on http://0.0.0.0:3111/ (Press CTRL+C to quit)
INFO:app:Metrics request successfull
ERROR:app:Exception on /metrics [GET]
Traceback (most recent call last):
  File "/Users/alex/opt/anaconda3/lib/python3.8/site-packages/flask/app.py", line 2447, in wsgi_app
    response = self.full_dispatch_request()
  File "/Users/alex/opt/anaconda3/lib/python3.8/site-packages/flask/app.py", line 1952, in full_dispatch_request
    rv = self.handle_user_exception(e)
  File "/Users/alex/opt/anaconda3/lib/python3.8/site-packages/flask/app.py", line 1821, in handle_user_exception
    reraise(exc_type, exc_value, tb)
  File "/Users/alex/opt/anaconda3/lib/python3.8/site-packages/flask/_compat.py", line 39, in reraise
    raise value
  File "/Users/alex/opt/anaconda3/lib/python3.8/site-packages/flask/app.py", line 1950, in full_dispatch_request
    rv = self.dispatch_request()
  File "/Users/alex/opt/anaconda3/lib/python3.8/site-packages/flask/app.py", line 1936, in dispatch_request
    return self.view_functions[rule.endpoint](**req.view_args)
  File "app.py", line 103, in metrics
    return jsonify(response)
  File "/Users/alex/opt/anaconda3/lib/python3.8/site-packages/flask/json/__init__.py", line 370, in jsonify
    dumps(data, indent=indent, separators=separators) + "\n",
  File "/Users/alex/opt/anaconda3/lib/python3.8/site-packages/flask/json/__init__.py", line 211, in dumps
    rv = _json.dumps(obj, **kwargs)
  File "/Users/alex/opt/anaconda3/lib/python3.8/json/__init__.py", line 234, in dumps
    return cls(
  File "/Users/alex/opt/anaconda3/lib/python3.8/json/encoder.py", line 199, in encode
    chunks = self.iterencode(o, _one_shot=True)
  File "/Users/alex/opt/anaconda3/lib/python3.8/json/encoder.py", line 257, in iterencode
    return _iterencode(o, 0)
  File "/Users/alex/opt/anaconda3/lib/python3.8/site-packages/flask/json/__init__.py", line 100, in default
    return _json.JSONEncoder.default(self, o)
  File "/Users/alex/opt/anaconda3/lib/python3.8/json/encoder.py", line 179, in default
    raise TypeError(f'Object of type {o.__class__.__name__} '
TypeError: Object of type Response is not JSON serializable
INFO:werkzeug:127.0.0.1 - - [08/Jun/2021 19:59:18] "[35m[1mGET /metrics HTTP/1.1[0m" 500 -
INFO:app:Metrics request successfull
ERROR:app:Exception on /metrics [GET]
Traceback (most recent call last):
  File "/Users/alex/opt/anaconda3/lib/python3.8/site-packages/flask/app.py", line 2447, in wsgi_app
    response = self.full_dispatch_request()
  File "/Users/alex/opt/anaconda3/lib/python3.8/site-packages/flask/app.py", line 1952, in full_dispatch_request
    rv = self.handle_user_exception(e)
  File "/Users/alex/opt/anaconda3/lib/python3.8/site-packages/flask/app.py", line 1821, in handle_user_exception
    reraise(exc_type, exc_value, tb)
  File "/Users/alex/opt/anaconda3/lib/python3.8/site-packages/flask/_compat.py", line 39, in reraise
    raise value
  File "/Users/alex/opt/anaconda3/lib/python3.8/site-packages/flask/app.py", line 1950, in full_dispatch_request
    rv = self.dispatch_request()
  File "/Users/alex/opt/anaconda3/lib/python3.8/site-packages/flask/app.py", line 1936, in dispatch_request
    return self.view_functions[rule.endpoint](**req.view_args)
  File "app.py", line 103, in metrics
    return jsonify(response)
  File "/Users/alex/opt/anaconda3/lib/python3.8/site-packages/flask/json/__init__.py", line 370, in jsonify
    dumps(data, indent=indent, separators=separators) + "\n",
  File "/Users/alex/opt/anaconda3/lib/python3.8/site-packages/flask/json/__init__.py", line 211, in dumps
    rv = _json.dumps(obj, **kwargs)
  File "/Users/alex/opt/anaconda3/lib/python3.8/json/__init__.py", line 234, in dumps
    return cls(
  File "/Users/alex/opt/anaconda3/lib/python3.8/json/encoder.py", line 199, in encode
    chunks = self.iterencode(o, _one_shot=True)
  File "/Users/alex/opt/anaconda3/lib/python3.8/json/encoder.py", line 257, in iterencode
    return _iterencode(o, 0)
  File "/Users/alex/opt/anaconda3/lib/python3.8/site-packages/flask/json/__init__.py", line 100, in default
    return _json.JSONEncoder.default(self, o)
  File "/Users/alex/opt/anaconda3/lib/python3.8/json/encoder.py", line 179, in default
    raise TypeError(f'Object of type {o.__class__.__name__} '
TypeError: Object of type Response is not JSON serializable
INFO:werkzeug:127.0.0.1 - - [08/Jun/2021 19:59:18] "[35m[1mGET /metrics HTTP/1.1[0m" 500 -
INFO:werkzeug: * Running on http://0.0.0.0:3111/ (Press CTRL+C to quit)
INFO:app:Metrics request successfull
INFO:werkzeug:127.0.0.1 - - [08/Jun/2021 20:01:37] "[35m[1mGET /metrics HTTP/1.1[0m" 500 -
ERROR:werkzeug:Error on request:
Traceback (most recent call last):
  File "/Users/alex/opt/anaconda3/lib/python3.8/site-packages/werkzeug/serving.py", line 323, in run_wsgi
    execute(self.server.app)
  File "/Users/alex/opt/anaconda3/lib/python3.8/site-packages/werkzeug/serving.py", line 314, in execute
    for data in application_iter:
  File "/Users/alex/opt/anaconda3/lib/python3.8/site-packages/werkzeug/wsgi.py", line 506, in __next__
    return self._next()
  File "/Users/alex/opt/anaconda3/lib/python3.8/site-packages/werkzeug/wrappers/base_response.py", line 45, in _iter_encoded
    for item in iterable:
TypeError: 'Response' object is not iterable
INFO:app:Metrics request successfull
INFO:werkzeug:127.0.0.1 - - [08/Jun/2021 20:01:38] "[35m[1mGET /metrics HTTP/1.1[0m" 500 -
ERROR:werkzeug:Error on request:
Traceback (most recent call last):
  File "/Users/alex/opt/anaconda3/lib/python3.8/site-packages/werkzeug/serving.py", line 323, in run_wsgi
    execute(self.server.app)
  File "/Users/alex/opt/anaconda3/lib/python3.8/site-packages/werkzeug/serving.py", line 314, in execute
    for data in application_iter:
  File "/Users/alex/opt/anaconda3/lib/python3.8/site-packages/werkzeug/wsgi.py", line 506, in __next__
    return self._next()
  File "/Users/alex/opt/anaconda3/lib/python3.8/site-packages/werkzeug/wrappers/base_response.py", line 45, in _iter_encoded
    for item in iterable:
TypeError: 'Response' object is not iterable
INFO:werkzeug: * Running on http://0.0.0.0:3111/ (Press CTRL+C to quit)
INFO:app:Metrics request successfull
ERROR:app:Exception on /metrics [GET]
Traceback (most recent call last):
  File "/Users/alex/opt/anaconda3/lib/python3.8/site-packages/flask/app.py", line 2447, in wsgi_app
    response = self.full_dispatch_request()
  File "/Users/alex/opt/anaconda3/lib/python3.8/site-packages/flask/app.py", line 1952, in full_dispatch_request
    rv = self.handle_user_exception(e)
  File "/Users/alex/opt/anaconda3/lib/python3.8/site-packages/flask/app.py", line 1821, in handle_user_exception
    reraise(exc_type, exc_value, tb)
  File "/Users/alex/opt/anaconda3/lib/python3.8/site-packages/flask/_compat.py", line 39, in reraise
    raise value
  File "/Users/alex/opt/anaconda3/lib/python3.8/site-packages/flask/app.py", line 1950, in full_dispatch_request
    rv = self.dispatch_request()
  File "/Users/alex/opt/anaconda3/lib/python3.8/site-packages/flask/app.py", line 1936, in dispatch_request
    return self.view_functions[rule.endpoint](**req.view_args)
  File "app.py", line 100, in metrics
    return jsonify(response)
  File "/Users/alex/opt/anaconda3/lib/python3.8/site-packages/flask/json/__init__.py", line 370, in jsonify
    dumps(data, indent=indent, separators=separators) + "\n",
  File "/Users/alex/opt/anaconda3/lib/python3.8/site-packages/flask/json/__init__.py", line 211, in dumps
    rv = _json.dumps(obj, **kwargs)
  File "/Users/alex/opt/anaconda3/lib/python3.8/json/__init__.py", line 234, in dumps
    return cls(
  File "/Users/alex/opt/anaconda3/lib/python3.8/json/encoder.py", line 199, in encode
    chunks = self.iterencode(o, _one_shot=True)
  File "/Users/alex/opt/anaconda3/lib/python3.8/json/encoder.py", line 257, in iterencode
    return _iterencode(o, 0)
  File "/Users/alex/opt/anaconda3/lib/python3.8/site-packages/flask/json/__init__.py", line 100, in default
    return _json.JSONEncoder.default(self, o)
  File "/Users/alex/opt/anaconda3/lib/python3.8/json/encoder.py", line 179, in default
    raise TypeError(f'Object of type {o.__class__.__name__} '
TypeError: Object of type Response is not JSON serializable
INFO:werkzeug:127.0.0.1 - - [08/Jun/2021 20:02:48] "[35m[1mGET /metrics HTTP/1.1[0m" 500 -
INFO:app:Metrics request successfull
ERROR:app:Exception on /metrics [GET]
Traceback (most recent call last):
  File "/Users/alex/opt/anaconda3/lib/python3.8/site-packages/flask/app.py", line 2447, in wsgi_app
    response = self.full_dispatch_request()
  File "/Users/alex/opt/anaconda3/lib/python3.8/site-packages/flask/app.py", line 1952, in full_dispatch_request
    rv = self.handle_user_exception(e)
  File "/Users/alex/opt/anaconda3/lib/python3.8/site-packages/flask/app.py", line 1821, in handle_user_exception
    reraise(exc_type, exc_value, tb)
  File "/Users/alex/opt/anaconda3/lib/python3.8/site-packages/flask/_compat.py", line 39, in reraise
    raise value
  File "/Users/alex/opt/anaconda3/lib/python3.8/site-packages/flask/app.py", line 1950, in full_dispatch_request
    rv = self.dispatch_request()
  File "/Users/alex/opt/anaconda3/lib/python3.8/site-packages/flask/app.py", line 1936, in dispatch_request
    return self.view_functions[rule.endpoint](**req.view_args)
  File "app.py", line 100, in metrics
    return jsonify(response)
  File "/Users/alex/opt/anaconda3/lib/python3.8/site-packages/flask/json/__init__.py", line 370, in jsonify
    dumps(data, indent=indent, separators=separators) + "\n",
  File "/Users/alex/opt/anaconda3/lib/python3.8/site-packages/flask/json/__init__.py", line 211, in dumps
    rv = _json.dumps(obj, **kwargs)
  File "/Users/alex/opt/anaconda3/lib/python3.8/json/__init__.py", line 234, in dumps
    return cls(
  File "/Users/alex/opt/anaconda3/lib/python3.8/json/encoder.py", line 199, in encode
    chunks = self.iterencode(o, _one_shot=True)
  File "/Users/alex/opt/anaconda3/lib/python3.8/json/encoder.py", line 257, in iterencode
    return _iterencode(o, 0)
  File "/Users/alex/opt/anaconda3/lib/python3.8/site-packages/flask/json/__init__.py", line 100, in default
    return _json.JSONEncoder.default(self, o)
  File "/Users/alex/opt/anaconda3/lib/python3.8/json/encoder.py", line 179, in default
    raise TypeError(f'Object of type {o.__class__.__name__} '
TypeError: Object of type Response is not JSON serializable
INFO:werkzeug:127.0.0.1 - - [08/Jun/2021 20:02:49] "[35m[1mGET /metrics HTTP/1.1[0m" 500 -
INFO:werkzeug: * Running on http://0.0.0.0:3111/ (Press CTRL+C to quit)
INFO:app:Metrics request successfull
INFO:werkzeug:127.0.0.1 - - [08/Jun/2021 20:07:13] "[35m[1mGET /metrics HTTP/1.1[0m" 500 -
ERROR:werkzeug:Error on request:
Traceback (most recent call last):
  File "/Users/alex/opt/anaconda3/lib/python3.8/site-packages/werkzeug/serving.py", line 323, in run_wsgi
    execute(self.server.app)
  File "/Users/alex/opt/anaconda3/lib/python3.8/site-packages/werkzeug/serving.py", line 314, in execute
    for data in application_iter:
  File "/Users/alex/opt/anaconda3/lib/python3.8/site-packages/werkzeug/wsgi.py", line 506, in __next__
    return self._next()
  File "/Users/alex/opt/anaconda3/lib/python3.8/site-packages/werkzeug/wrappers/base_response.py", line 45, in _iter_encoded
    for item in iterable:
TypeError: 'Response' object is not iterable
INFO:app:Metrics request successfull
INFO:werkzeug:127.0.0.1 - - [08/Jun/2021 20:07:14] "[35m[1mGET /metrics HTTP/1.1[0m" 500 -
ERROR:werkzeug:Error on request:
Traceback (most recent call last):
  File "/Users/alex/opt/anaconda3/lib/python3.8/site-packages/werkzeug/serving.py", line 323, in run_wsgi
    execute(self.server.app)
  File "/Users/alex/opt/anaconda3/lib/python3.8/site-packages/werkzeug/serving.py", line 314, in execute
    for data in application_iter:
  File "/Users/alex/opt/anaconda3/lib/python3.8/site-packages/werkzeug/wsgi.py", line 506, in __next__
    return self._next()
  File "/Users/alex/opt/anaconda3/lib/python3.8/site-packages/werkzeug/wrappers/base_response.py", line 45, in _iter_encoded
    for item in iterable:
TypeError: 'Response' object is not iterable
INFO:werkzeug: * Running on http://0.0.0.0:3111/ (Press CTRL+C to quit)
INFO:app:Metrics request successfull
INFO:werkzeug:127.0.0.1 - - [08/Jun/2021 20:07:37] "[35m[1mGET /metrics HTTP/1.1[0m" 500 -
ERROR:werkzeug:Error on request:
Traceback (most recent call last):
  File "/Users/alex/opt/anaconda3/lib/python3.8/site-packages/werkzeug/serving.py", line 323, in run_wsgi
    execute(self.server.app)
  File "/Users/alex/opt/anaconda3/lib/python3.8/site-packages/werkzeug/serving.py", line 314, in execute
    for data in application_iter:
  File "/Users/alex/opt/anaconda3/lib/python3.8/site-packages/werkzeug/wsgi.py", line 506, in __next__
    return self._next()
  File "/Users/alex/opt/anaconda3/lib/python3.8/site-packages/werkzeug/wrappers/base_response.py", line 45, in _iter_encoded
    for item in iterable:
TypeError: 'Response' object is not iterable
INFO:app:Metrics request successfull
INFO:werkzeug:127.0.0.1 - - [08/Jun/2021 20:07:38] "[35m[1mGET /metrics HTTP/1.1[0m" 500 -
ERROR:werkzeug:Error on request:
Traceback (most recent call last):
  File "/Users/alex/opt/anaconda3/lib/python3.8/site-packages/werkzeug/serving.py", line 323, in run_wsgi
    execute(self.server.app)
  File "/Users/alex/opt/anaconda3/lib/python3.8/site-packages/werkzeug/serving.py", line 314, in execute
    for data in application_iter:
  File "/Users/alex/opt/anaconda3/lib/python3.8/site-packages/werkzeug/wsgi.py", line 506, in __next__
    return self._next()
  File "/Users/alex/opt/anaconda3/lib/python3.8/site-packages/werkzeug/wrappers/base_response.py", line 45, in _iter_encoded
    for item in iterable:
TypeError: 'Response' object is not iterable
INFO:werkzeug: * Running on http://0.0.0.0:3111/ (Press CTRL+C to quit)
INFO:app:Metrics request successfull
INFO:werkzeug:127.0.0.1 - - [08/Jun/2021 20:08:13] "[35m[1mGET /metrics HTTP/1.1[0m" 500 -
ERROR:werkzeug:Error on request:
Traceback (most recent call last):
  File "/Users/alex/opt/anaconda3/lib/python3.8/site-packages/werkzeug/serving.py", line 323, in run_wsgi
    execute(self.server.app)
  File "/Users/alex/opt/anaconda3/lib/python3.8/site-packages/werkzeug/serving.py", line 314, in execute
    for data in application_iter:
  File "/Users/alex/opt/anaconda3/lib/python3.8/site-packages/werkzeug/wsgi.py", line 506, in __next__
    return self._next()
  File "/Users/alex/opt/anaconda3/lib/python3.8/site-packages/werkzeug/wrappers/base_response.py", line 45, in _iter_encoded
    for item in iterable:
TypeError: 'Response' object is not iterable
INFO:app:Metrics request successfull
INFO:werkzeug:127.0.0.1 - - [08/Jun/2021 20:08:14] "[35m[1mGET /metrics HTTP/1.1[0m" 500 -
ERROR:werkzeug:Error on request:
Traceback (most recent call last):
  File "/Users/alex/opt/anaconda3/lib/python3.8/site-packages/werkzeug/serving.py", line 323, in run_wsgi
    execute(self.server.app)
  File "/Users/alex/opt/anaconda3/lib/python3.8/site-packages/werkzeug/serving.py", line 314, in execute
    for data in application_iter:
  File "/Users/alex/opt/anaconda3/lib/python3.8/site-packages/werkzeug/wsgi.py", line 506, in __next__
    return self._next()
  File "/Users/alex/opt/anaconda3/lib/python3.8/site-packages/werkzeug/wrappers/base_response.py", line 45, in _iter_encoded
    for item in iterable:
TypeError: 'Response' object is not iterable
INFO:app:Metrics request successfull
INFO:werkzeug:127.0.0.1 - - [08/Jun/2021 20:08:14] "[35m[1mGET /metrics HTTP/1.1[0m" 500 -
ERROR:werkzeug:Error on request:
Traceback (most recent call last):
  File "/Users/alex/opt/anaconda3/lib/python3.8/site-packages/werkzeug/serving.py", line 323, in run_wsgi
    execute(self.server.app)
  File "/Users/alex/opt/anaconda3/lib/python3.8/site-packages/werkzeug/serving.py", line 314, in execute
    for data in application_iter:
  File "/Users/alex/opt/anaconda3/lib/python3.8/site-packages/werkzeug/wsgi.py", line 506, in __next__
    return self._next()
  File "/Users/alex/opt/anaconda3/lib/python3.8/site-packages/werkzeug/wrappers/base_response.py", line 45, in _iter_encoded
    for item in iterable:
TypeError: 'Response' object is not iterable
INFO:werkzeug: * Running on http://0.0.0.0:3111/ (Press CTRL+C to quit)
INFO:app:Metrics request successfull
ERROR:app:Exception on /metrics [GET]
Traceback (most recent call last):
  File "/Users/alex/opt/anaconda3/lib/python3.8/site-packages/werkzeug/wrappers/base_response.py", line 298, in status_code
    self._status = "%d %s" % (code, HTTP_STATUS_CODES[code].upper())
KeyError: <Response 0 bytes [200 OK]>

During handling of the above exception, another exception occurred:

Traceback (most recent call last):
  File "/Users/alex/opt/anaconda3/lib/python3.8/site-packages/flask/app.py", line 2447, in wsgi_app
    response = self.full_dispatch_request()
  File "/Users/alex/opt/anaconda3/lib/python3.8/site-packages/flask/app.py", line 1953, in full_dispatch_request
    return self.finalize_request(rv)
  File "/Users/alex/opt/anaconda3/lib/python3.8/site-packages/flask/app.py", line 1968, in finalize_request
    response = self.make_response(rv)
  File "/Users/alex/opt/anaconda3/lib/python3.8/site-packages/flask/app.py", line 2139, in make_response
    rv.status_code = status
  File "/Users/alex/opt/anaconda3/lib/python3.8/site-packages/werkzeug/wrappers/base_response.py", line 300, in status_code
    self._status = "%d UNKNOWN" % code
TypeError: %d format: a number is required, not Response
INFO:werkzeug:127.0.0.1 - - [08/Jun/2021 20:16:36] "[35m[1mGET /metrics HTTP/1.1[0m" 500 -
INFO:app:Metrics request successfull
ERROR:app:Exception on /metrics [GET]
Traceback (most recent call last):
  File "/Users/alex/opt/anaconda3/lib/python3.8/site-packages/werkzeug/wrappers/base_response.py", line 298, in status_code
    self._status = "%d %s" % (code, HTTP_STATUS_CODES[code].upper())
KeyError: <Response 0 bytes [200 OK]>

During handling of the above exception, another exception occurred:

Traceback (most recent call last):
  File "/Users/alex/opt/anaconda3/lib/python3.8/site-packages/flask/app.py", line 2447, in wsgi_app
    response = self.full_dispatch_request()
  File "/Users/alex/opt/anaconda3/lib/python3.8/site-packages/flask/app.py", line 1953, in full_dispatch_request
    return self.finalize_request(rv)
  File "/Users/alex/opt/anaconda3/lib/python3.8/site-packages/flask/app.py", line 1968, in finalize_request
    response = self.make_response(rv)
  File "/Users/alex/opt/anaconda3/lib/python3.8/site-packages/flask/app.py", line 2139, in make_response
    rv.status_code = status
  File "/Users/alex/opt/anaconda3/lib/python3.8/site-packages/werkzeug/wrappers/base_response.py", line 300, in status_code
    self._status = "%d UNKNOWN" % code
TypeError: %d format: a number is required, not Response
INFO:werkzeug:127.0.0.1 - - [08/Jun/2021 20:16:37] "[35m[1mGET /metrics HTTP/1.1[0m" 500 -
INFO:werkzeug: * Running on http://0.0.0.0:3111/ (Press CTRL+C to quit)
INFO:app:Metrics request successfull
INFO:werkzeug:127.0.0.1 - - [08/Jun/2021 20:17:25] "[37mGET /metrics HTTP/1.1[0m" 200 -
INFO:app:Metrics request successfull
INFO:werkzeug:127.0.0.1 - - [08/Jun/2021 20:17:28] "[37mGET /metrics HTTP/1.1[0m" 200 -
INFO:app:Metrics request successfull
INFO:werkzeug:127.0.0.1 - - [08/Jun/2021 20:17:29] "[37mGET /metrics HTTP/1.1[0m" 200 -
INFO:app:Metrics request successfull
INFO:werkzeug:127.0.0.1 - - [08/Jun/2021 20:17:29] "[37mGET /metrics HTTP/1.1[0m" 200 -
INFO:app:Metrics request successfull
INFO:werkzeug:127.0.0.1 - - [08/Jun/2021 20:17:29] "[37mGET /metrics HTTP/1.1[0m" 200 -
INFO:app:Metrics request successfull
INFO:werkzeug:127.0.0.1 - - [08/Jun/2021 20:17:30] "[37mGET /metrics HTTP/1.1[0m" 200 -
INFO:app:Metrics request successfull
INFO:werkzeug:127.0.0.1 - - [08/Jun/2021 20:17:30] "[37mGET /metrics HTTP/1.1[0m" 200 -
INFO:app:Metrics request successfull
INFO:werkzeug:127.0.0.1 - - [08/Jun/2021 20:17:30] "[37mGET /metrics HTTP/1.1[0m" 200 -
INFO:app:Metrics request successfull
INFO:werkzeug:127.0.0.1 - - [08/Jun/2021 20:17:30] "[37mGET /metrics HTTP/1.1[0m" 200 -
INFO:app:Metrics request successfull
INFO:werkzeug:127.0.0.1 - - [08/Jun/2021 20:17:30] "[37mGET /metrics HTTP/1.1[0m" 200 -
INFO:app:Metrics request successfull
INFO:werkzeug:127.0.0.1 - - [08/Jun/2021 20:17:31] "[37mGET /metrics HTTP/1.1[0m" 200 -
INFO:app:Metrics request successfull
INFO:werkzeug:127.0.0.1 - - [08/Jun/2021 20:17:31] "[37mGET /metrics HTTP/1.1[0m" 200 -
INFO:app:Metrics request successfull
INFO:werkzeug:127.0.0.1 - - [08/Jun/2021 20:17:31] "[37mGET /metrics HTTP/1.1[0m" 200 -
INFO:app:Metrics request successfull
INFO:werkzeug:127.0.0.1 - - [08/Jun/2021 20:17:31] "[37mGET /metrics HTTP/1.1[0m" 200 -
INFO:app:Metrics request successfull
INFO:werkzeug:127.0.0.1 - - [08/Jun/2021 20:17:31] "[37mGET /metrics HTTP/1.1[0m" 200 -
INFO:app:Metrics request successfull
INFO:werkzeug:127.0.0.1 - - [08/Jun/2021 20:17:31] "[37mGET /metrics HTTP/1.1[0m" 200 -
INFO:app:Metrics request successfull
INFO:werkzeug:127.0.0.1 - - [08/Jun/2021 20:17:32] "[37mGET /metrics HTTP/1.1[0m" 200 -
INFO:app:Metrics request successfull
INFO:werkzeug:127.0.0.1 - - [08/Jun/2021 20:17:32] "[37mGET /metrics HTTP/1.1[0m" 200 -
INFO:app:Metrics request successfull
INFO:werkzeug:127.0.0.1 - - [08/Jun/2021 20:17:32] "[37mGET /metrics HTTP/1.1[0m" 200 -
INFO:app:Metrics request successfull
INFO:werkzeug:127.0.0.1 - - [08/Jun/2021 20:17:32] "[37mGET /metrics HTTP/1.1[0m" 200 -
INFO:app:Metrics request successfull
INFO:werkzeug:127.0.0.1 - - [08/Jun/2021 20:17:32] "[37mGET /metrics HTTP/1.1[0m" 200 -
INFO:werkzeug:127.0.0.1 - - [08/Jun/2021 20:17:44] "[37mGET / HTTP/1.1[0m" 200 -
INFO:werkzeug:127.0.0.1 - - [08/Jun/2021 20:17:45] "[37mGET /1 HTTP/1.1[0m" 200 -
INFO:werkzeug:127.0.0.1 - - [08/Jun/2021 20:17:47] "[37mGET / HTTP/1.1[0m" 200 -
INFO:werkzeug:127.0.0.1 - - [08/Jun/2021 20:17:48] "[37mGET /2 HTTP/1.1[0m" 200 -
INFO:werkzeug:127.0.0.1 - - [08/Jun/2021 20:17:49] "[37mGET / HTTP/1.1[0m" 200 -
INFO:werkzeug:127.0.0.1 - - [08/Jun/2021 20:17:50] "[37mGET /4 HTTP/1.1[0m" 200 -
INFO:werkzeug:127.0.0.1 - - [08/Jun/2021 20:17:52] "[37mGET / HTTP/1.1[0m" 200 -
INFO:werkzeug:127.0.0.1 - - [08/Jun/2021 20:17:53] "[37mGET /4 HTTP/1.1[0m" 200 -
INFO:werkzeug:127.0.0.1 - - [08/Jun/2021 20:17:55] "[37mGET / HTTP/1.1[0m" 200 -
INFO:werkzeug:127.0.0.1 - - [08/Jun/2021 20:17:56] "[37mGET /5 HTTP/1.1[0m" 200 -
INFO:werkzeug:127.0.0.1 - - [08/Jun/2021 20:17:57] "[37mGET / HTTP/1.1[0m" 200 -
INFO:app:Metrics request successfull
INFO:werkzeug:127.0.0.1 - - [08/Jun/2021 20:18:02] "[37mGET /metrics HTTP/1.1[0m" 200 -
INFO:werkzeug: * Running on http://0.0.0.0:3111/ (Press CTRL+C to quit)
INFO:app:Metrics request successfull
INFO:werkzeug:127.0.0.1 - - [08/Jun/2021 20:18:53] "[37mGET /metrics HTTP/1.1[0m" 200 -
INFO:app:Metrics request successfull
INFO:werkzeug:127.0.0.1 - - [08/Jun/2021 20:18:54] "[37mGET /metrics HTTP/1.1[0m" 200 -
INFO:werkzeug: * Running on http://0.0.0.0:3111/ (Press CTRL+C to quit)
INFO:app:Metrics request successfull
ERROR:app:Exception on /metrics [GET]
Traceback (most recent call last):
  File "/Users/alex/opt/anaconda3/lib/python3.8/site-packages/flask/app.py", line 2447, in wsgi_app
    response = self.full_dispatch_request()
  File "/Users/alex/opt/anaconda3/lib/python3.8/site-packages/flask/app.py", line 1952, in full_dispatch_request
    rv = self.handle_user_exception(e)
  File "/Users/alex/opt/anaconda3/lib/python3.8/site-packages/flask/app.py", line 1821, in handle_user_exception
    reraise(exc_type, exc_value, tb)
  File "/Users/alex/opt/anaconda3/lib/python3.8/site-packages/flask/_compat.py", line 39, in reraise
    raise value
  File "/Users/alex/opt/anaconda3/lib/python3.8/site-packages/flask/app.py", line 1950, in full_dispatch_request
    rv = self.dispatch_request()
  File "/Users/alex/opt/anaconda3/lib/python3.8/site-packages/flask/app.py", line 1936, in dispatch_request
    return self.view_functions[rule.endpoint](**req.view_args)
  File "app.py", line 103, in metrics
    return jsonify(data)
  File "/Users/alex/opt/anaconda3/lib/python3.8/site-packages/flask/json/__init__.py", line 370, in jsonify
    dumps(data, indent=indent, separators=separators) + "\n",
  File "/Users/alex/opt/anaconda3/lib/python3.8/site-packages/flask/json/__init__.py", line 211, in dumps
    rv = _json.dumps(obj, **kwargs)
  File "/Users/alex/opt/anaconda3/lib/python3.8/json/__init__.py", line 234, in dumps
    return cls(
  File "/Users/alex/opt/anaconda3/lib/python3.8/json/encoder.py", line 199, in encode
    chunks = self.iterencode(o, _one_shot=True)
  File "/Users/alex/opt/anaconda3/lib/python3.8/json/encoder.py", line 257, in iterencode
    return _iterencode(o, 0)
  File "/Users/alex/opt/anaconda3/lib/python3.8/site-packages/flask/json/__init__.py", line 100, in default
    return _json.JSONEncoder.default(self, o)
  File "/Users/alex/opt/anaconda3/lib/python3.8/json/encoder.py", line 179, in default
    raise TypeError(f'Object of type {o.__class__.__name__} '
TypeError: Object of type Row is not JSON serializable
INFO:werkzeug:127.0.0.1 - - [08/Jun/2021 20:20:48] "[35m[1mGET /metrics HTTP/1.1[0m" 500 -
INFO:werkzeug: * Running on http://0.0.0.0:3111/ (Press CTRL+C to quit)
INFO:app:Metrics request successfull
INFO:werkzeug:127.0.0.1 - - [08/Jun/2021 20:21:27] "[37mGET /metrics HTTP/1.1[0m" 200 -
INFO:app:Metrics request successfull
INFO:werkzeug:127.0.0.1 - - [08/Jun/2021 20:21:27] "[37mGET /metrics HTTP/1.1[0m" 200 -
INFO:werkzeug: * Running on http://0.0.0.0:3111/ (Press CTRL+C to quit)
INFO:app:Metrics request successfull
INFO:werkzeug:127.0.0.1 - - [08/Jun/2021 20:22:36] "[37mGET /metrics HTTP/1.1[0m" 200 -
INFO:werkzeug: * Running on http://0.0.0.0:3111/ (Press CTRL+C to quit)
ERROR:app:Exception on /metrics [GET]
Traceback (most recent call last):
  File "/Users/alex/opt/anaconda3/lib/python3.8/site-packages/flask/app.py", line 2447, in wsgi_app
    response = self.full_dispatch_request()
  File "/Users/alex/opt/anaconda3/lib/python3.8/site-packages/flask/app.py", line 1952, in full_dispatch_request
    rv = self.handle_user_exception(e)
  File "/Users/alex/opt/anaconda3/lib/python3.8/site-packages/flask/app.py", line 1821, in handle_user_exception
    reraise(exc_type, exc_value, tb)
  File "/Users/alex/opt/anaconda3/lib/python3.8/site-packages/flask/_compat.py", line 39, in reraise
    raise value
  File "/Users/alex/opt/anaconda3/lib/python3.8/site-packages/flask/app.py", line 1950, in full_dispatch_request
    rv = self.dispatch_request()
  File "/Users/alex/opt/anaconda3/lib/python3.8/site-packages/flask/app.py", line 1936, in dispatch_request
    return self.view_functions[rule.endpoint](**req.view_args)
  File "app.py", line 94, in metrics
    "count_articles":[row[0] for row in count_posts][0]
  File "app.py", line 94, in <listcomp>
    "count_articles":[row[0] for row in count_posts][0]
TypeError: 'int' object is not subscriptable
INFO:werkzeug:127.0.0.1 - - [08/Jun/2021 20:23:24] "[35m[1mGET /metrics HTTP/1.1[0m" 500 -
ERROR:app:Exception on /metrics [GET]
Traceback (most recent call last):
  File "/Users/alex/opt/anaconda3/lib/python3.8/site-packages/flask/app.py", line 2447, in wsgi_app
    response = self.full_dispatch_request()
  File "/Users/alex/opt/anaconda3/lib/python3.8/site-packages/flask/app.py", line 1952, in full_dispatch_request
    rv = self.handle_user_exception(e)
  File "/Users/alex/opt/anaconda3/lib/python3.8/site-packages/flask/app.py", line 1821, in handle_user_exception
    reraise(exc_type, exc_value, tb)
  File "/Users/alex/opt/anaconda3/lib/python3.8/site-packages/flask/_compat.py", line 39, in reraise
    raise value
  File "/Users/alex/opt/anaconda3/lib/python3.8/site-packages/flask/app.py", line 1950, in full_dispatch_request
    rv = self.dispatch_request()
  File "/Users/alex/opt/anaconda3/lib/python3.8/site-packages/flask/app.py", line 1936, in dispatch_request
    return self.view_functions[rule.endpoint](**req.view_args)
  File "app.py", line 94, in metrics
    "count_articles":[row[0] for row in count_posts][0]
  File "app.py", line 94, in <listcomp>
    "count_articles":[row[0] for row in count_posts][0]
TypeError: 'int' object is not subscriptable
INFO:werkzeug:127.0.0.1 - - [08/Jun/2021 20:23:25] "[35m[1mGET /metrics HTTP/1.1[0m" 500 -
INFO:werkzeug: * Running on http://0.0.0.0:3111/ (Press CTRL+C to quit)
INFO:app:Metrics request successfull
INFO:werkzeug:127.0.0.1 - - [08/Jun/2021 20:23:39] "[37mGET /metrics HTTP/1.1[0m" 200 -
INFO:werkzeug:127.0.0.1 - - [08/Jun/2021 20:24:11] "[37mGET / HTTP/1.1[0m" 200 -
INFO:app:Metrics request successfull
INFO:werkzeug:127.0.0.1 - - [08/Jun/2021 20:24:21] "[37mGET /metrics HTTP/1.1[0m" 200 -
INFO:werkzeug: * Running on http://0.0.0.0:3111/ (Press CTRL+C to quit)
ERROR:app:Exception on /metrics [GET]
Traceback (most recent call last):
  File "/Users/alex/opt/anaconda3/lib/python3.8/site-packages/flask/app.py", line 2447, in wsgi_app
    response = self.full_dispatch_request()
  File "/Users/alex/opt/anaconda3/lib/python3.8/site-packages/flask/app.py", line 1952, in full_dispatch_request
    rv = self.handle_user_exception(e)
  File "/Users/alex/opt/anaconda3/lib/python3.8/site-packages/flask/app.py", line 1821, in handle_user_exception
    reraise(exc_type, exc_value, tb)
  File "/Users/alex/opt/anaconda3/lib/python3.8/site-packages/flask/_compat.py", line 39, in reraise
    raise value
  File "/Users/alex/opt/anaconda3/lib/python3.8/site-packages/flask/app.py", line 1950, in full_dispatch_request
    rv = self.dispatch_request()
  File "/Users/alex/opt/anaconda3/lib/python3.8/site-packages/flask/app.py", line 1936, in dispatch_request
    return self.view_functions[rule.endpoint](**req.view_args)
  File "app.py", line 96, in metrics
    response = app.response_class(
TypeError: __init__() got an unexpected keyword argument 'message'
INFO:werkzeug:127.0.0.1 - - [08/Jun/2021 20:25:50] "[35m[1mGET /metrics HTTP/1.1[0m" 500 -
ERROR:app:Exception on /metrics [GET]
Traceback (most recent call last):
  File "/Users/alex/opt/anaconda3/lib/python3.8/site-packages/flask/app.py", line 2447, in wsgi_app
    response = self.full_dispatch_request()
  File "/Users/alex/opt/anaconda3/lib/python3.8/site-packages/flask/app.py", line 1952, in full_dispatch_request
    rv = self.handle_user_exception(e)
  File "/Users/alex/opt/anaconda3/lib/python3.8/site-packages/flask/app.py", line 1821, in handle_user_exception
    reraise(exc_type, exc_value, tb)
  File "/Users/alex/opt/anaconda3/lib/python3.8/site-packages/flask/_compat.py", line 39, in reraise
    raise value
  File "/Users/alex/opt/anaconda3/lib/python3.8/site-packages/flask/app.py", line 1950, in full_dispatch_request
    rv = self.dispatch_request()
  File "/Users/alex/opt/anaconda3/lib/python3.8/site-packages/flask/app.py", line 1936, in dispatch_request
    return self.view_functions[rule.endpoint](**req.view_args)
  File "app.py", line 96, in metrics
    response = app.response_class(
TypeError: __init__() got an unexpected keyword argument 'message'
INFO:werkzeug:127.0.0.1 - - [08/Jun/2021 20:25:51] "[35m[1mGET /metrics HTTP/1.1[0m" 500 -
INFO:werkzeug: * Running on http://0.0.0.0:3111/ (Press CTRL+C to quit)
INFO:app:Metrics request successfull
INFO:werkzeug:127.0.0.1 - - [08/Jun/2021 20:26:28] "[35m[1mGET /metrics HTTP/1.1[0m" 500 -
ERROR:werkzeug:Error on request:
Traceback (most recent call last):
  File "/Users/alex/opt/anaconda3/lib/python3.8/site-packages/werkzeug/serving.py", line 323, in run_wsgi
    execute(self.server.app)
  File "/Users/alex/opt/anaconda3/lib/python3.8/site-packages/werkzeug/serving.py", line 314, in execute
    for data in application_iter:
  File "/Users/alex/opt/anaconda3/lib/python3.8/site-packages/werkzeug/wsgi.py", line 506, in __next__
    return self._next()
  File "/Users/alex/opt/anaconda3/lib/python3.8/site-packages/werkzeug/wrappers/base_response.py", line 45, in _iter_encoded
    for item in iterable:
TypeError: 'Response' object is not iterable
INFO:app:Metrics request successfull
INFO:werkzeug:127.0.0.1 - - [08/Jun/2021 20:26:29] "[35m[1mGET /metrics HTTP/1.1[0m" 500 -
ERROR:werkzeug:Error on request:
Traceback (most recent call last):
  File "/Users/alex/opt/anaconda3/lib/python3.8/site-packages/werkzeug/serving.py", line 323, in run_wsgi
    execute(self.server.app)
  File "/Users/alex/opt/anaconda3/lib/python3.8/site-packages/werkzeug/serving.py", line 314, in execute
    for data in application_iter:
  File "/Users/alex/opt/anaconda3/lib/python3.8/site-packages/werkzeug/wsgi.py", line 506, in __next__
    return self._next()
  File "/Users/alex/opt/anaconda3/lib/python3.8/site-packages/werkzeug/wrappers/base_response.py", line 45, in _iter_encoded
    for item in iterable:
TypeError: 'Response' object is not iterable
INFO:werkzeug: * Running on http://0.0.0.0:3111/ (Press CTRL+C to quit)
INFO:app:Metrics request successfull
INFO:werkzeug:127.0.0.1 - - [08/Jun/2021 20:27:25] "[35m[1mGET /metrics HTTP/1.1[0m" 500 -
ERROR:werkzeug:Error on request:
Traceback (most recent call last):
  File "/Users/alex/opt/anaconda3/lib/python3.8/site-packages/werkzeug/serving.py", line 323, in run_wsgi
    execute(self.server.app)
  File "/Users/alex/opt/anaconda3/lib/python3.8/site-packages/werkzeug/serving.py", line 314, in execute
    for data in application_iter:
  File "/Users/alex/opt/anaconda3/lib/python3.8/site-packages/werkzeug/wsgi.py", line 506, in __next__
    return self._next()
  File "/Users/alex/opt/anaconda3/lib/python3.8/site-packages/werkzeug/wrappers/base_response.py", line 45, in _iter_encoded
    for item in iterable:
TypeError: 'Response' object is not iterable
INFO:app:Metrics request successfull
INFO:werkzeug:127.0.0.1 - - [08/Jun/2021 20:27:26] "[35m[1mGET /metrics HTTP/1.1[0m" 500 -
ERROR:werkzeug:Error on request:
Traceback (most recent call last):
  File "/Users/alex/opt/anaconda3/lib/python3.8/site-packages/werkzeug/serving.py", line 323, in run_wsgi
    execute(self.server.app)
  File "/Users/alex/opt/anaconda3/lib/python3.8/site-packages/werkzeug/serving.py", line 314, in execute
    for data in application_iter:
  File "/Users/alex/opt/anaconda3/lib/python3.8/site-packages/werkzeug/wsgi.py", line 506, in __next__
    return self._next()
  File "/Users/alex/opt/anaconda3/lib/python3.8/site-packages/werkzeug/wrappers/base_response.py", line 45, in _iter_encoded
    for item in iterable:
TypeError: 'Response' object is not iterable
INFO:app:Metrics request successfull
INFO:werkzeug:127.0.0.1 - - [08/Jun/2021 20:35:08] "[35m[1mGET /metrics HTTP/1.1[0m" 500 -
ERROR:werkzeug:Error on request:
Traceback (most recent call last):
  File "/Users/alex/opt/anaconda3/lib/python3.8/site-packages/werkzeug/serving.py", line 323, in run_wsgi
    execute(self.server.app)
  File "/Users/alex/opt/anaconda3/lib/python3.8/site-packages/werkzeug/serving.py", line 314, in execute
    for data in application_iter:
  File "/Users/alex/opt/anaconda3/lib/python3.8/site-packages/werkzeug/wsgi.py", line 506, in __next__
    return self._next()
  File "/Users/alex/opt/anaconda3/lib/python3.8/site-packages/werkzeug/wrappers/base_response.py", line 45, in _iter_encoded
    for item in iterable:
TypeError: 'Response' object is not iterable
INFO:app:Metrics request successfull
INFO:werkzeug:127.0.0.1 - - [08/Jun/2021 20:35:09] "[35m[1mGET /metrics HTTP/1.1[0m" 500 -
ERROR:werkzeug:Error on request:
Traceback (most recent call last):
  File "/Users/alex/opt/anaconda3/lib/python3.8/site-packages/werkzeug/serving.py", line 323, in run_wsgi
    execute(self.server.app)
  File "/Users/alex/opt/anaconda3/lib/python3.8/site-packages/werkzeug/serving.py", line 314, in execute
    for data in application_iter:
  File "/Users/alex/opt/anaconda3/lib/python3.8/site-packages/werkzeug/wsgi.py", line 506, in __next__
    return self._next()
  File "/Users/alex/opt/anaconda3/lib/python3.8/site-packages/werkzeug/wrappers/base_response.py", line 45, in _iter_encoded
    for item in iterable:
TypeError: 'Response' object is not iterable
INFO:werkzeug: * Running on http://0.0.0.0:3111/ (Press CTRL+C to quit)
INFO:werkzeug: * Running on http://0.0.0.0:3111/ (Press CTRL+C to quit)
INFO:app:Metrics request successfull
INFO:werkzeug:127.0.0.1 - - [08/Jun/2021 20:47:14] "[37mGET /metrics HTTP/1.1[0m" 200 -
INFO:app:Metrics request successfull
INFO:werkzeug:127.0.0.1 - - [08/Jun/2021 20:47:50] "[37mGET /metrics HTTP/1.1[0m" 200 -
INFO:werkzeug: * Running on http://0.0.0.0:3111/ (Press CTRL+C to quit)
INFO:app:Metrics request successfull
INFO:werkzeug:127.0.0.1 - - [08/Jun/2021 20:47:59] "[37mGET /metrics HTTP/1.1[0m" 200 -
INFO:werkzeug: * Running on http://0.0.0.0:3111/ (Press CTRL+C to quit)
INFO:app:Metrics request successfull
ERROR:app:Exception on /metrics [GET]
Traceback (most recent call last):
  File "/Users/alex/opt/anaconda3/lib/python3.8/site-packages/flask/app.py", line 2447, in wsgi_app
    response = self.full_dispatch_request()
  File "/Users/alex/opt/anaconda3/lib/python3.8/site-packages/flask/app.py", line 1952, in full_dispatch_request
    rv = self.handle_user_exception(e)
  File "/Users/alex/opt/anaconda3/lib/python3.8/site-packages/flask/app.py", line 1821, in handle_user_exception
    reraise(exc_type, exc_value, tb)
  File "/Users/alex/opt/anaconda3/lib/python3.8/site-packages/flask/_compat.py", line 39, in reraise
    raise value
  File "/Users/alex/opt/anaconda3/lib/python3.8/site-packages/flask/app.py", line 1950, in full_dispatch_request
    rv = self.dispatch_request()
  File "/Users/alex/opt/anaconda3/lib/python3.8/site-packages/flask/app.py", line 1936, in dispatch_request
    return self.view_functions[rule.endpoint](**req.view_args)
  File "app.py", line 103, in metrics
    return jsonify(response)
  File "/Users/alex/opt/anaconda3/lib/python3.8/site-packages/flask/json/__init__.py", line 370, in jsonify
    dumps(data, indent=indent, separators=separators) + "\n",
  File "/Users/alex/opt/anaconda3/lib/python3.8/site-packages/flask/json/__init__.py", line 211, in dumps
    rv = _json.dumps(obj, **kwargs)
  File "/Users/alex/opt/anaconda3/lib/python3.8/json/__init__.py", line 234, in dumps
    return cls(
  File "/Users/alex/opt/anaconda3/lib/python3.8/json/encoder.py", line 199, in encode
    chunks = self.iterencode(o, _one_shot=True)
  File "/Users/alex/opt/anaconda3/lib/python3.8/json/encoder.py", line 257, in iterencode
    return _iterencode(o, 0)
  File "/Users/alex/opt/anaconda3/lib/python3.8/site-packages/flask/json/__init__.py", line 100, in default
    return _json.JSONEncoder.default(self, o)
  File "/Users/alex/opt/anaconda3/lib/python3.8/json/encoder.py", line 179, in default
    raise TypeError(f'Object of type {o.__class__.__name__} '
TypeError: Object of type Response is not JSON serializable
INFO:werkzeug:127.0.0.1 - - [08/Jun/2021 20:48:21] "[35m[1mGET /metrics HTTP/1.1[0m" 500 -
INFO:werkzeug: * Running on http://0.0.0.0:3111/ (Press CTRL+C to quit)
INFO:app:Metrics request successfull
INFO:werkzeug:127.0.0.1 - - [08/Jun/2021 20:48:41] "[37mGET /metrics HTTP/1.1[0m" 200 -
INFO:app:Metrics request successfull
INFO:werkzeug:127.0.0.1 - - [08/Jun/2021 20:48:42] "[37mGET /metrics HTTP/1.1[0m" 200 -
INFO:app:Metrics request successfull
INFO:werkzeug:127.0.0.1 - - [08/Jun/2021 20:48:43] "[37mGET /metrics HTTP/1.1[0m" 200 -
INFO:app:Metrics request successfull
INFO:werkzeug:127.0.0.1 - - [08/Jun/2021 20:48:43] "[37mGET /metrics HTTP/1.1[0m" 200 -
INFO:app:Metrics request successfull
INFO:werkzeug:127.0.0.1 - - [08/Jun/2021 20:48:43] "[37mGET /metrics HTTP/1.1[0m" 200 -
INFO:app:Metrics request successfull
INFO:werkzeug:127.0.0.1 - - [08/Jun/2021 20:48:44] "[37mGET /metrics HTTP/1.1[0m" 200 -
INFO:app:Metrics request successfull
INFO:werkzeug:127.0.0.1 - - [08/Jun/2021 20:48:44] "[37mGET /metrics HTTP/1.1[0m" 200 -
INFO:app:Metrics request successfull
INFO:werkzeug:127.0.0.1 - - [08/Jun/2021 20:48:44] "[37mGET /metrics HTTP/1.1[0m" 200 -
INFO:app:Metrics request successfull
INFO:werkzeug:127.0.0.1 - - [08/Jun/2021 20:48:44] "[37mGET /metrics HTTP/1.1[0m" 200 -
INFO:app:Metrics request successfull
INFO:werkzeug:127.0.0.1 - - [08/Jun/2021 20:48:44] "[37mGET /metrics HTTP/1.1[0m" 200 -
INFO:app:Metrics request successfull
INFO:werkzeug:127.0.0.1 - - [08/Jun/2021 20:48:44] "[37mGET /metrics HTTP/1.1[0m" 200 -
INFO:app:Metrics request successfull
INFO:werkzeug:127.0.0.1 - - [08/Jun/2021 20:48:45] "[37mGET /metrics HTTP/1.1[0m" 200 -
INFO:app:Metrics request successfull
INFO:werkzeug:127.0.0.1 - - [08/Jun/2021 20:48:45] "[37mGET /metrics HTTP/1.1[0m" 200 -
INFO:app:Metrics request successfull
INFO:werkzeug:127.0.0.1 - - [08/Jun/2021 20:48:45] "[37mGET /metrics HTTP/1.1[0m" 200 -
INFO:app:Metrics request successfull
INFO:werkzeug:127.0.0.1 - - [08/Jun/2021 20:48:45] "[37mGET /metrics HTTP/1.1[0m" 200 -
INFO:app:Metrics request successfull
INFO:werkzeug:127.0.0.1 - - [08/Jun/2021 20:48:45] "[37mGET /metrics HTTP/1.1[0m" 200 -
INFO:app:Metrics request successfull
INFO:werkzeug:127.0.0.1 - - [08/Jun/2021 20:48:46] "[37mGET /metrics HTTP/1.1[0m" 200 -
INFO:app:Metrics request successfull
INFO:werkzeug:127.0.0.1 - - [08/Jun/2021 20:48:46] "[37mGET /metrics HTTP/1.1[0m" 200 -
INFO:app:Metrics request successfull
INFO:werkzeug:127.0.0.1 - - [08/Jun/2021 20:48:46] "[37mGET /metrics HTTP/1.1[0m" 200 -
INFO:app:Status request successfull
INFO:werkzeug:127.0.0.1 - - [08/Jun/2021 20:49:42] "[37mGET /healthz HTTP/1.1[0m" 200 -
INFO:app:Status request successfull
INFO:werkzeug:127.0.0.1 - - [08/Jun/2021 20:50:04] "[37mGET /healthz HTTP/1.1[0m" 200 -
INFO:werkzeug: * Running on http://0.0.0.0:3111/ (Press CTRL+C to quit)
INFO:app:Metrics request successfull
INFO:werkzeug:127.0.0.1 - - [08/Jun/2021 20:56:17] "[37mGET /metrics HTTP/1.1[0m" 200 -
INFO:app:Metrics request successfull
INFO:werkzeug:127.0.0.1 - - [08/Jun/2021 20:56:20] "[37mGET /metrics HTTP/1.1[0m" 200 -
INFO:app:Metrics request successfull
INFO:werkzeug:127.0.0.1 - - [08/Jun/2021 23:27:48] "[37mGET /metrics HTTP/1.1[0m" 200 -
INFO:app:Metrics request successfull
INFO:werkzeug:127.0.0.1 - - [08/Jun/2021 23:27:49] "[37mGET /metrics HTTP/1.1[0m" 200 -
INFO:app:Metrics request successfull
INFO:werkzeug:127.0.0.1 - - [08/Jun/2021 23:27:50] "[37mGET /metrics HTTP/1.1[0m" 200 -
INFO:app:Metrics request successfull
INFO:werkzeug:127.0.0.1 - - [08/Jun/2021 23:27:50] "[37mGET /metrics HTTP/1.1[0m" 200 -
INFO:app:Metrics request successfull
INFO:werkzeug:127.0.0.1 - - [08/Jun/2021 23:27:50] "[37mGET /metrics HTTP/1.1[0m" 200 -
